{"name": "Not auth user cannot open dataset page and auth user callback url dataset", "status": "failed", "statusDetails": {"message": "AssertionError: The current url is not as expected. Actual: https://app.proofminder.com/, Expected: https://app.proofminder.com/dataset\n", "trace": "  File \"/Users/solteszattila/dev/python BDD/venv_bdd_py3_s3/lib/python3.9/site-packages/behave/model.py\", line 1329, in run\n    match.run(runner.context)\n  File \"/Users/solteszattila/dev/python BDD/venv_bdd_py3_s3/lib/python3.9/site-packages/behave/matchers.py\", line 98, in run\n    self.func(context, *args, **kwargs)\n  File \"features/steps/steps.py\", line 64, in step_impl\n    hpf.assert_current_url(context, url)\n  File \"/Users/solteszattila/dev/python BDD/proofminder/helpers/helperFuncs.py\", line 55, in assert_current_url\n    assert current_url == expected_url, \"The current url is not as expected.\" \\\n"}, "steps": [{"name": "Given \"dataset\" page", "status": "passed", "start": 1630344909796, "stop": 1630344910338}, {"name": "Then I am redirected to \"login\" page", "status": "passed", "start": 1630344910338, "stop": 1630344912350}, {"name": "When I enter an email address which is associated to test user in the database", "status": "passed", "start": 1630344912351, "stop": 1630344912426}, {"name": "And the correct password of the user", "status": "passed", "start": 1630344912426, "stop": 1630344912459}, {"name": "And I click \"submit\" button", "status": "passed", "start": 1630344912459, "stop": 1630344912479}, {"name": "Then I am redirected to \"dataset\" page", "status": "failed", "statusDetails": {"message": "AssertionError: The current url is not as expected. Actual: https://app.proofminder.com/, Expected: https://app.proofminder.com/dataset\n", "trace": "  File \"/Users/solteszattila/dev/python BDD/venv_bdd_py3_s3/lib/python3.9/site-packages/behave/model.py\", line 1329, in run\n    match.run(runner.context)\n  File \"/Users/solteszattila/dev/python BDD/venv_bdd_py3_s3/lib/python3.9/site-packages/behave/matchers.py\", line 98, in run\n    self.func(context, *args, **kwargs)\n  File \"features/steps/steps.py\", line 64, in step_impl\n    hpf.assert_current_url(context, url)\n  File \"/Users/solteszattila/dev/python BDD/proofminder/helpers/helperFuncs.py\", line 55, in assert_current_url\n    assert current_url == expected_url, \"The current url is not as expected.\" \\\n"}, "start": 1630344912479, "stop": 1630344914676}], "start": 1630344909795, "stop": 1630344914676, "uuid": "0f3f5424-a324-4e1b-8352-aad4aaf52a6f", "historyId": "95fad4bf50cb03089cb54432f5243490", "fullName": "Basic tests of mainapp: Not auth user cannot open dataset page and auth user callback url dataset", "labels": [{"name": "severity", "value": "normal"}, {"name": "feature", "value": "Basic tests of mainapp"}, {"name": "framework", "value": "behave"}, {"name": "language", "value": "cpython3"}]}